<?xml version="1.0" ?>
<!-- =================================================================================== -->
<!-- |    This document was autogenerated by xacro from rpd_manipulator_7sk.urdf.xacro | -->
<!-- |    EDITING THIS FILE BY HAND IS NOT RECOMMENDED                                 | -->
<!-- =================================================================================== -->
<robot name="rpd_manipulator_7sk">
  <material name="black">
    <color rgba="0 0 0 1"/>
  </material>
  <material name="red">
    <color rgba="1 0 0 1"/>
  </material>
  <material name="green">
    <color rgba="0 1 0 1"/>
  </material>
  <material name="blue">
    <color rgba="0 0 1 1"/>
  </material>
  <material name="white">
    <color rgba="1 1 1 1"/>
  </material>
  <!-- world link & world to base link joint-->
  <link name="world"/>
  <joint name="fixed_joint" type="fixed">
    <origin rpy="0 0 0" xyz="0 0 0"/>
    <parent link="world"/>
    <child link="base_link"/>
  </joint>
  <link name="base_link">
    <visual>
      <origin rpy="0 0 0" xyz="-0.0269962 0.0 0.036055"/>
      <geometry>
        <mesh filename="file:///home/cherry/Documents/ros2_workspaces/rpd_ws/install/rpd_manipulator_7sk_description/share/rpd_manipulator_7sk_description/meshes/base_link.stl" scale="0.001 0.001 0.001"/>
      </geometry>
      <material name="red"/>
    </visual>
    <collision>
      <origin rpy="0 0 0" xyz="-0.0269962 0.0 0.036055"/>
      <geometry>
        <mesh filename="file:///home/cherry/Documents/ros2_workspaces/rpd_ws/install/rpd_manipulator_7sk_description/share/rpd_manipulator_7sk_description/meshes/base_link.stl" scale="0.001 0.001 0.001"/>
      </geometry>
    </collision>
    <inertial>
      <mass value="0.05"/>
      <origin rpy="0 0 0" xyz="-0.0269962 0.0 0.036055"/>
      <inertia ixx="1e-05" ixy="0" ixz="0" iyy="1e-05" iyz="0" izz="1e-05"/>
    </inertial>
  </link>
  <link name="link_1">
    <visual>
      <origin rpy="0 0 0" xyz="0.0 0.0 0.0251809"/>
      <geometry>
        <mesh filename="file:///home/cherry/Documents/ros2_workspaces/rpd_ws/install/rpd_manipulator_7sk_description/share/rpd_manipulator_7sk_description/meshes/link_1.stl" scale="0.001 0.001 0.001"/>
      </geometry>
      <material name="red"/>
    </visual>
    <collision>
      <origin rpy="0 0 0" xyz="0.0 0.0 0.0251809"/>
      <geometry>
        <mesh filename="file:///home/cherry/Documents/ros2_workspaces/rpd_ws/install/rpd_manipulator_7sk_description/share/rpd_manipulator_7sk_description/meshes/link_1.stl" scale="0.001 0.001 0.001"/>
      </geometry>
    </collision>
    <inertial>
      <mass value="0.05"/>
      <origin rpy="0 0 0" xyz="0.0 0.0 0.0251809"/>
      <inertia ixx="1e-05" ixy="0" ixz="0" iyy="1e-05" iyz="0" izz="1e-05"/>
    </inertial>
  </link>
  <link name="link_2">
    <visual>
      <origin rpy="0 0 0" xyz="0.0 0.0 0.02885"/>
      <geometry>
        <mesh filename="file:///home/cherry/Documents/ros2_workspaces/rpd_ws/install/rpd_manipulator_7sk_description/share/rpd_manipulator_7sk_description/meshes/link_2.stl" scale="0.001 0.001 0.001"/>
      </geometry>
      <material name="red"/>
    </visual>
    <collision>
      <origin rpy="0 0 0" xyz="0.0 0.0 0.02885"/>
      <geometry>
        <mesh filename="file:///home/cherry/Documents/ros2_workspaces/rpd_ws/install/rpd_manipulator_7sk_description/share/rpd_manipulator_7sk_description/meshes/link_2.stl" scale="0.001 0.001 0.001"/>
      </geometry>
    </collision>
    <inertial>
      <mass value="0.05"/>
      <origin rpy="0 0 0" xyz="0.0 0.0 0.02885"/>
      <inertia ixx="1e-05" ixy="0" ixz="0" iyy="1e-05" iyz="0" izz="1e-05"/>
    </inertial>
  </link>
  <link name="link_3">
    <visual>
      <origin rpy="0 0 0" xyz="0.0138059 0.0 0.08125"/>
      <geometry>
        <mesh filename="file:///home/cherry/Documents/ros2_workspaces/rpd_ws/install/rpd_manipulator_7sk_description/share/rpd_manipulator_7sk_description/meshes/link_3.stl" scale="0.001 0.001 0.001"/>
      </geometry>
      <material name="red"/>
    </visual>
    <collision>
      <origin rpy="0 0 0" xyz="0.0138059 0.0 0.08125"/>
      <geometry>
        <mesh filename="file:///home/cherry/Documents/ros2_workspaces/rpd_ws/install/rpd_manipulator_7sk_description/share/rpd_manipulator_7sk_description/meshes/link_3.stl" scale="0.001 0.001 0.001"/>
      </geometry>
    </collision>
    <inertial>
      <mass value="0.05"/>
      <origin rpy="0 0 0" xyz="0.0138059 0.0 0.08125"/>
      <inertia ixx="1e-05" ixy="0" ixz="0" iyy="1e-05" iyz="0" izz="1e-05"/>
    </inertial>
  </link>
  <link name="link_4">
    <visual>
      <origin rpy="0 0 0" xyz="0.02885 0.0 0.0"/>
      <geometry>
        <mesh filename="file:///home/cherry/Documents/ros2_workspaces/rpd_ws/install/rpd_manipulator_7sk_description/share/rpd_manipulator_7sk_description/meshes/link_4.stl" scale="0.001 0.001 0.001"/>
      </geometry>
      <material name="red"/>
    </visual>
    <collision>
      <origin rpy="0 0 0" xyz="0.02885 0.0 0.0"/>
      <geometry>
        <mesh filename="file:///home/cherry/Documents/ros2_workspaces/rpd_ws/install/rpd_manipulator_7sk_description/share/rpd_manipulator_7sk_description/meshes/link_4.stl" scale="0.001 0.001 0.001"/>
      </geometry>
    </collision>
    <inertial>
      <mass value="0.05"/>
      <origin rpy="0 0 0" xyz="0.02885 0.0 0.0"/>
      <inertia ixx="1e-05" ixy="0" ixz="0" iyy="1e-05" iyz="0" izz="1e-05"/>
    </inertial>
  </link>
  <link name="link_5">
    <visual>
      <origin rpy="0 0 0" xyz="0.0251808 0.0 0.0"/>
      <geometry>
        <mesh filename="file:///home/cherry/Documents/ros2_workspaces/rpd_ws/install/rpd_manipulator_7sk_description/share/rpd_manipulator_7sk_description/meshes/link_5.stl" scale="0.001 0.001 0.001"/>
      </geometry>
      <material name="red"/>
    </visual>
    <collision>
      <origin rpy="0 0 0" xyz="0.0251808 0.0 0.0"/>
      <geometry>
        <mesh filename="file:///home/cherry/Documents/ros2_workspaces/rpd_ws/install/rpd_manipulator_7sk_description/share/rpd_manipulator_7sk_description/meshes/link_5.stl" scale="0.001 0.001 0.001"/>
      </geometry>
    </collision>
    <inertial>
      <mass value="0.05"/>
      <origin rpy="0 0 0" xyz="0.0251808 0.0 0.0"/>
      <inertia ixx="1e-05" ixy="0" ixz="0" iyy="1e-05" iyz="0" izz="1e-05"/>
    </inertial>
  </link>
  <link name="link_6">
    <visual>
      <origin rpy="0 0 0" xyz="0.032182 0.0 0.0"/>
      <geometry>
        <mesh filename="file:///home/cherry/Documents/ros2_workspaces/rpd_ws/install/rpd_manipulator_7sk_description/share/rpd_manipulator_7sk_description/meshes/link_6.stl" scale="0.001 0.001 0.001"/>
      </geometry>
      <material name="red"/>
    </visual>
    <collision>
      <origin rpy="0 0 0" xyz="0.032182 0.0 0.0"/>
      <geometry>
        <mesh filename="file:///home/cherry/Documents/ros2_workspaces/rpd_ws/install/rpd_manipulator_7sk_description/share/rpd_manipulator_7sk_description/meshes/link_6.stl" scale="0.001 0.001 0.001"/>
      </geometry>
    </collision>
    <inertial>
      <mass value="0.05"/>
      <origin rpy="0 0 0" xyz="0.032182 0.0 0.0"/>
      <inertia ixx="1e-05" ixy="0" ixz="0" iyy="1e-05" iyz="0" izz="1e-05"/>
    </inertial>
  </link>
  <link name="gripper_base_link">
    <visual>
      <origin rpy="0 0 0" xyz="0.0293 0.0 0.00546"/>
      <geometry>
        <mesh filename="file:///home/cherry/Documents/ros2_workspaces/rpd_ws/install/rpd_manipulator_7sk_description/share/rpd_manipulator_7sk_description/meshes/gripper_base_link.stl" scale="0.001 0.001 0.001"/>
      </geometry>
      <material name="red"/>
    </visual>
    <collision>
      <origin rpy="0 0 0" xyz="0.0293 0.0 0.00546"/>
      <geometry>
        <mesh filename="file:///home/cherry/Documents/ros2_workspaces/rpd_ws/install/rpd_manipulator_7sk_description/share/rpd_manipulator_7sk_description/meshes/gripper_base_link.stl" scale="0.001 0.001 0.001"/>
      </geometry>
    </collision>
    <inertial>
      <mass value="0.05"/>
      <origin rpy="0 0 0" xyz="0.0293 0.0 0.00546"/>
      <inertia ixx="1e-05" ixy="0" ixz="0" iyy="1e-05" iyz="0" izz="1e-05"/>
    </inertial>
  </link>
  <link name="gripper_left_link">
    <visual>
      <origin rpy="0 0 0" xyz="0.0224 0.0 0.0001"/>
      <geometry>
        <mesh filename="file:///home/cherry/Documents/ros2_workspaces/rpd_ws/install/rpd_manipulator_7sk_description/share/rpd_manipulator_7sk_description/meshes/gripper_left_link.stl" scale="0.001 0.001 0.001"/>
      </geometry>
      <material name="red"/>
    </visual>
    <collision>
      <origin rpy="0 0 0" xyz="0.0224 0.0 0.0001"/>
      <geometry>
        <mesh filename="file:///home/cherry/Documents/ros2_workspaces/rpd_ws/install/rpd_manipulator_7sk_description/share/rpd_manipulator_7sk_description/meshes/gripper_left_link.stl" scale="0.001 0.001 0.001"/>
      </geometry>
    </collision>
    <inertial>
      <mass value="0.05"/>
      <origin rpy="0 0 0" xyz="0.0224 0.0 0.0001"/>
      <inertia ixx="1e-05" ixy="0" ixz="0" iyy="1e-05" iyz="0" izz="1e-05"/>
    </inertial>
  </link>
  <link name="gripper_right_link">
    <visual>
      <origin rpy="0 0 0" xyz="0.0224 0.0 0.0001"/>
      <geometry>
        <mesh filename="file:///home/cherry/Documents/ros2_workspaces/rpd_ws/install/rpd_manipulator_7sk_description/share/rpd_manipulator_7sk_description/meshes/gripper_right_link.stl" scale="0.001 0.001 0.001"/>
      </geometry>
      <material name="red"/>
    </visual>
    <collision>
      <origin rpy="0 0 0" xyz="0.0224 0.0 0.0001"/>
      <geometry>
        <mesh filename="file:///home/cherry/Documents/ros2_workspaces/rpd_ws/install/rpd_manipulator_7sk_description/share/rpd_manipulator_7sk_description/meshes/gripper_right_link.stl" scale="0.001 0.001 0.001"/>
      </geometry>
    </collision>
    <inertial>
      <mass value="0.05"/>
      <origin rpy="0 0 0" xyz="0.0224 0.0 0.0001"/>
      <inertia ixx="1e-05" ixy="0" ixz="0" iyy="1e-05" iyz="0" izz="1e-05"/>
    </inertial>
  </link>
  <joint name="joint_1" type="revolute">
    <origin rpy="0 0 0" xyz="0.0 0.0 0.07211"/>
    <limit effort="2.5" lower="-1.570796" upper="1.570796" velocity="2.094395"/>
    <axis xyz="0 0 -1"/>
    <parent link="base_link"/>
    <child link="link_1"/>
  </joint>
  <joint name="joint_2" type="revolute">
    <origin rpy="0 0 0" xyz="0.0 0.0 0.044202"/>
    <limit effort="2.5" lower="-1.570796" upper="1.570796" velocity="2.094395"/>
    <axis xyz="0 1 0"/>
    <parent link="link_1"/>
    <child link="link_2"/>
  </joint>
  <joint name="joint_3" type="revolute">
    <origin rpy="0 0 0" xyz="-0.0125 0.0 0.0702"/>
    <limit effort="2.5" lower="-3.14159" upper="3.14159" velocity="2.094395"/>
    <axis xyz="0 0 -1"/>
    <parent link="link_2"/>
    <child link="link_3"/>
  </joint>
  <joint name="joint_4" type="revolute">
    <origin rpy="0 0 0" xyz="0.0425 0.0 0.1375"/>
    <limit effort="2.5" lower="-1.570796" upper="1.04719755" velocity="2.094395"/>
    <axis xyz="0 1 0"/>
    <parent link="link_3"/>
    <child link="link_4"/>
  </joint>
  <joint name="joint_5" type="revolute">
    <origin rpy="0 0 0" xyz="0.0702 0.0 0.0125"/>
    <limit effort="2.5" lower="-3.14159" upper="3.14159" velocity="2.094395"/>
    <axis xyz="-1 0 0"/>
    <parent link="link_4"/>
    <child link="link_5"/>
  </joint>
  <joint name="joint_6" type="revolute">
    <origin rpy="0 0 0" xyz="0.0402502 0.0 0.0"/>
    <limit effort="2.5" lower="-1.570796" upper="1.570796" velocity="2.094395"/>
    <axis xyz="0 0 1"/>
    <parent link="link_5"/>
    <child link="link_6"/>
  </joint>
  <joint name="joint_7" type="revolute">
    <origin rpy="0 0 0" xyz="0.0647495 0.0 0.0"/>
    <limit effort="2.5" lower="-1.570796" upper="1.570796" velocity="2.094395"/>
    <axis xyz="0 1 0"/>
    <parent link="link_6"/>
    <child link="gripper_base_link"/>
  </joint>
  <joint name="gripper_left_joint" type="prismatic">
    <origin rpy="0 0 0" xyz="0.0670388 -0.0176793 -0.0011"/>
    <limit effort="2.5" lower="0.0" upper="0.037" velocity="2.094395"/>
    <axis xyz="0 1 0"/>
    <parent link="gripper_base_link"/>
    <child link="gripper_left_link"/>
  </joint>
  <joint name="gripper_right_joint" type="prismatic">
    <origin rpy="0 0 0" xyz="0.0670388 0.0176793 -0.0011"/>
    <limit effort="2.5" lower="0.0" upper="0.037" velocity="3.14159"/>
    <axis xyz="0 -1 0"/>
    <parent link="gripper_base_link"/>
    <child link="gripper_right_link"/>
    <mimic joint="gripper_left_joint" multiplier="1.0"/>
  </joint>
  <!-- end effector link -->
  <link name="end_effector_link">
    <visual>
      <origin rpy="0 0 0" xyz="0.0 0.0 0.0"/>
      <geometry>
        <sphere radius="0.005"/>
      </geometry>
      <material name="green"/>
    </visual>
  </link>
  <!-- end effector joint -->
  <joint name="end_effector_joint" type="fixed">
    <origin rpy="0 0 0" xyz="0.0970388 0.0 -0.0011"/>
    <parent link="gripper_base_link"/>
    <child link="end_effector_link"/>
  </joint>
  <gazebo reference="base_link">
    <kp>1000000.0</kp>
    <kd>100.0</kd>
    <mu1>30.0</mu1>
    <mu2>30.0</mu2>
    <maxVel>1.0</maxVel>
    <minDepth>0.001</minDepth>
  </gazebo>
  <gazebo reference="link_1">
    <kp>1000000.0</kp>
    <kd>100.0</kd>
    <mu1>30.0</mu1>
    <mu2>30.0</mu2>
    <maxVel>1.0</maxVel>
    <minDepth>0.001</minDepth>
  </gazebo>
  <gazebo reference="link_2">
    <kp>1000000.0</kp>
    <kd>100.0</kd>
    <mu1>30.0</mu1>
    <mu2>30.0</mu2>
    <maxVel>1.0</maxVel>
    <minDepth>0.001</minDepth>
  </gazebo>
  <gazebo reference="link_3">
    <kp>1000000.0</kp>
    <kd>100.0</kd>
    <mu1>30.0</mu1>
    <mu2>30.0</mu2>
    <maxVel>1.0</maxVel>
    <minDepth>0.001</minDepth>
  </gazebo>
  <gazebo reference="link_4">
    <kp>1000000.0</kp>
    <kd>100.0</kd>
    <mu1>30.0</mu1>
    <mu2>30.0</mu2>
    <maxVel>1.0</maxVel>
    <minDepth>0.001</minDepth>
  </gazebo>
  <gazebo reference="link_5">
    <kp>1000000.0</kp>
    <kd>100.0</kd>
    <mu1>30.0</mu1>
    <mu2>30.0</mu2>
    <maxVel>1.0</maxVel>
    <minDepth>0.001</minDepth>
  </gazebo>
  <gazebo reference="link_6">
    <kp>1000000.0</kp>
    <kd>100.0</kd>
    <mu1>30.0</mu1>
    <mu2>30.0</mu2>
    <maxVel>1.0</maxVel>
    <minDepth>0.001</minDepth>
  </gazebo>
  <gazebo reference="gripper_base_link">
    <kp>1000000.0</kp>
    <kd>100.0</kd>
    <mu1>30.0</mu1>
    <mu2>30.0</mu2>
    <maxVel>1.0</maxVel>
    <minDepth>0.001</minDepth>
  </gazebo>
  <gazebo reference="gripper_left_link">
    <kp>1000000.0</kp>
    <kd>100.0</kd>
    <mu1>30.0</mu1>
    <mu2>30.0</mu2>
    <maxVel>1.0</maxVel>
    <minDepth>0.001</minDepth>
  </gazebo>
  <gazebo reference="gripper_right_link">
    <kp>1000000.0</kp>
    <kd>100.0</kd>
    <mu1>30.0</mu1>
    <mu2>30.0</mu2>
    <maxVel>1.0</maxVel>
    <minDepth>0.001</minDepth>
  </gazebo>
  <gazebo reference="end_effector_link"/>
  <gazebo>
    <plugin filename="gz-sim-joint-state-publisher-system" name="gz::sim::systems::JointStatePublisher">
      <joint_name>fixed_joint</joint_name>
      <joint_name>joint_1</joint_name>
      <joint_name>joint_2</joint_name>
      <joint_name>joint_3</joint_name>
      <joint_name>joint_4</joint_name>
      <joint_name>joint_5</joint_name>
      <joint_name>joint_6</joint_name>
      <joint_name>joint_7</joint_name>
      <joint_name>gripper_left_joint</joint_name>
      <joint_name>gripper_right_joint</joint_name>
    </plugin>
  </gazebo>
  <gazebo>
    <plugin filename="gz_ros2_control-system" name="gz_ros2_control::GazeboSimROS2ControlPlugin">
      <parameters>/home/cherry/Documents/ros2_workspaces/rpd_ws/install/rpd_manipulator_7sk_bringup/share/rpd_manipulator_7sk_bringup/config/rpd_manipulator_7sk_controllers.yaml</parameters>
    </plugin>
  </gazebo>
  <ros2_control name="RPDManipulator7SKSystem" type="system">
    <hardware>
      <plugin>rpd_manipulator_7sk_hardware/RPDManipulator7SKHardwareInterface</plugin>
      <param name="port">/dev/ttyACM0</param>
      <param name="baudrate">1000000</param>
    </hardware>
    <joint name="joint_1">
      <state_interface name="position"/>
      <state_interface name="velocity"/>
      <command_interface name="position"/>
      <param name="motor_id">71</param>
      <param name="gear_reduction">2.0</param>
    </joint>
    <joint name="joint_2">
      <state_interface name="position"/>
      <state_interface name="velocity"/>
      <command_interface name="position"/>
      <param name="motor_id">72</param>
      <param name="gear_reduction">1.0</param>
    </joint>
    <joint name="joint_3">
      <state_interface name="position"/>
      <state_interface name="velocity"/>
      <command_interface name="position"/>
      <param name="motor_id">73</param>
      <param name="gear_reduction">1.0</param>
    </joint>
    <joint name="joint_4">
      <state_interface name="position"/>
      <state_interface name="velocity"/>
      <command_interface name="position"/>
      <param name="motor_id">74</param>
      <param name="gear_reduction">1.0</param>
    </joint>
    <joint name="joint_5">
      <state_interface name="position"/>
      <state_interface name="velocity"/>
      <command_interface name="position"/>
      <param name="motor_id">75</param>
      <param name="gear_reduction">1.0</param>
    </joint>
    <joint name="joint_6">
      <state_interface name="position"/>
      <state_interface name="velocity"/>
      <command_interface name="position"/>
      <param name="motor_id">76</param>
      <param name="gear_reduction">1.0</param>
    </joint>
    <joint name="joint_7">
      <state_interface name="position"/>
      <state_interface name="velocity"/>
      <command_interface name="position"/>
      <param name="motor_id">77</param>
      <param name="gear_reduction">1.0</param>
    </joint>
    <joint name="gripper_left_joint">
      <state_interface name="position"/>
      <state_interface name="velocity"/>
      <command_interface name="position"/>
      <param name="motor_id">78</param>
      <param name="gear_reduction">1.0</param>
    </joint>
  </ros2_control>
</robot>
